Workbook

Sheet 요약
A1: 공공데이터포털(data.go.kr) 환경안전보건(EHS) 담당자용 API·파일데이터 목록
A2: 조사일: 2026-10-04 / 방법: 포털 키워드 검색(100여 개 EHS 키워드) + 핵심 EHS 기관 31곳 전체 데이터 수집 후 실무 관련성 기준 선별 / ★ = 우선 검토 추천
A4: 분야 | B4: 전체 | C4: 오픈API | D4: 파일데이터 | E4: ★핵심
A5: 01 법령·질의회시·Q&A·해석 | B5: =COUNTIF(전체목록!$A:$A,A5) | C5: =COUNTIFS(전체목록!$A:$A,A5,전체목록!$C:$C,"오픈API") | D5: =COUNTIFS(전체목록!$A:$A,A5,전체목록!$C:$C,"파일데이터") | E5: =COUNTIFS(전체목록!$A:$A,A5,전체목록!$B:$B,"★")
A6: 02 화학물질·MSDS·화학사고 | B6: =COUNTIF(전체목록!$A:$A,A6) | C6: =COUNTIFS(전체목록!$A:$A,A6,전체목록!$C:$C,"오픈API") | D6: =COUNTIFS(전체목록!$A:$A,A6,전체목록!$C:$C,"파일데이터") | E6: =COUNTIFS(전체목록!$A:$A,A6,전체목록!$B:$B,"★")
A7: 03 작업환경·보건관리·건강진단 | B7: =COUNTIF(전체목록!$A:$A,A7) | C7: =COUNTIFS(전체목록!$A:$A,A7,전체목록!$C:$C,"오픈API") | D7: =COUNTIFS(전체목록!$A:$A,A7,전체목록!$C:$C,"파일데이터") | E7: =COUNTIFS(전체목록!$A:$A,A7,전체목록!$B:$B,"★")
A8: 04 산업재해 통계·사고사례 | B8: =COUNTIF(전체목록!$A:$A,A8) | C8: =COUNTIFS(전체목록!$A:$A,A8,전체목록!$C:$C,"오픈API") | D8: =COUNTIFS(전체목록!$A:$A,A8,전체목록!$C:$C,"파일데이터") | E8: =COUNTIFS(전체목록!$A:$A,A8,전체목록!$B:$B,"★")
A9: 05 산재보험·보상·업무상질병 | B9: =COUNTIF(전체목록!$A:$A,A9) | C9: =COUNTIFS(전체목록!$A:$A,A9,전체목록!$C:$C,"오픈API") | D9: =COUNTIFS(전체목록!$A:$A,A9,전체목록!$C:$C,"파일데이터") | E9: =COUNTIFS(전체목록!$A:$A,A9,전체목록!$B:$B,"★")
A10: 06 안전보건 지정기관·인증·검사·교육기관 | B10: =COUNTIF(전체목록!$A:$A,A10) | C10: =COUNTIFS(전체목록!$A:$A,A10,전체목록!$C:$C,"오픈API") | D10: =COUNTIFS(전체목록!$A:$A,A10,전체목록!$C:$C,"파일데이터") | E10: =COUNTIFS(전체목록!$A:$A,A10,전체목록!$B:$B,"★")
A11: 07 안전보건 교육자료·매뉴얼·가이드 | B11: =COUNTIF(전체목록!$A:$A,A11) | C11: =COUNTIFS(전체목록!$A:$A,A11,전체목록!$C:$C,"오픈API") | D11: =COUNTIFS(전체목록!$A:$A,A11,전체목록!$C:$C,"파일데이터") | E11: =COUNTIFS(전체목록!$A:$A,A11,전체목록!$B:$B,"★")
A12: 08 폐기물·자원순환 | B12: =COUNTIF(전체목록!$A:$A,A12) | C12: =COUNTIFS(전체목록!$A:$A,A12,전체목록!$C:$C,"오픈API") | D12: =COUNTIFS(전체목록!$A:$A,A12,전체목록!$C:$C,"파일데이터") | E12: =COUNTIFS(전체목록!$A:$A,A12,전체목록!$B:$B,"★")
A13: 09 대기·수질·토양·환경측정 | B13: =COUNTIF(전체목록!$A:$A,A13) | C13: =COUNTIFS(전체목록!$A:$A,A13,전체목록!$C:$C,"오픈API") | D13: =COUNTIFS(전체목록!$A:$A,A13,전체목록!$C:$C,"파일데이터") | E13: =COUNTIFS(전체목록!$A:$A,A13,전체목록!$B:$B,"★")
A14: 10 환경 인허가·배출사업장·대행업체 | B14: =COUNTIF(전체목록!$A:$A,A14) | C14: =COUNTIFS(전체목록!$A:$A,A14,전체목록!$C:$C,"오픈API") | D14: =COUNTIFS(전체목록!$A:$A,A14,전체목록!$C:$C,"파일데이터") | E14: =COUNTIFS(전체목록!$A:$A,A14,전체목록!$B:$B,"★")
A15: 11 온실가스·환경정보공개·ESG·환경인증 | B15: =COUNTIF(전체목록!$A:$A,A15) | C15: =COUNTIFS(전체목록!$A:$A,A15,전체목록!$C:$C,"오픈API") | D15: =COUNTIFS(전체목록!$A:$A,A15,전체목록!$C:$C,"파일데이터") | E15: =COUNTIFS(전체목록!$A:$A,A15,전체목록!$B:$B,"★")
A16: 12 시설안전(가스·전기·승강기·소방·위험물·건설·방사선) | B16: =COUNTIF(전체목록!$A:$A,A16) | C16: =COUNTIFS(전체목록!$A:$A,A16,전체목록!$C:$C,"오픈API") | D16: =COUNTIFS(전체목록!$A:$A,A16,전체목록!$C:$C,"파일데이터") | E16: =COUNTIFS(전체목록!$A:$A,A16,전체목록!$B:$B,"★")
A17: 합계 | B17: =SUM(B5:B16) | C17: =SUM(C5:C16) | D17: =SUM(D5:D16) | E17: =SUM(E5:E16)
A19: 참고
A20: - 오픈API는 data.go.kr 로그인 후 "활용신청" → 인증키 발급 필요(대부분 개발계정 자동승인).
A21: - 파일데이터는 상세페이지에서 바로 다운로드(CSV/XLSX/PDF/HWP 등).
A22: - 지자체(시·군·구) 단위의 폐수/대기배출시설, 사업장폐기물배출자, 석면조사 대상 건축물 등은 수백 건이라 이 목록에서 제외. 필요 시 "OO시 폐수배출시설" 식으로 검색.
A23: - 행정안전부 "자원환경_" 계열(LOCALDATA 인허가)은 전국 인허가 대장이라 지자체 개별 데이터보다 우선 활용 권장.
A24: - "포털 외 자료" 시트: 요청 예시 중 data.go.kr에 등록되지 않은 자료(고용노동부 MSDS 질의회시집, 원주청 지정폐기물 사례집 등)의 원 출처.

Sheet 전체목록
A1: 분야 | B1: ★ | C1: 유형 | D1: 데이터명 | E1: 제공기관 | F1: 형식 | G1: 수정일 | H1: 링크 | I1: 설명(포털 요약)
A2: 01 법령·질의회시·Q&A·해석 | B2: ★ | C2: 오픈API | D2: 국민권익위원회_민원정책 질의응답조회서비스 | E2: 국민권익위원회 | F2: JSON | G2: 2026-09-23 | H2: https://www.data.go.kr/data/15074671/openapi.do | I2: 국민권익위원회는 민원정책에 대한 질의응답 데이터를 공개하여 공공 및 민간의 행정 연구에 활용할 수 있도록 지원하고 있습니다.
A3: 01 법령·질의회시·Q&A·해석 | B3: ★ | C3: 오픈API | D3: 근로복지공단_산재보험 판례 판결문 조회 서비스 | E3: 근로복지공단 | F3: XML | G3: 2026-01-12 | H3: https://www.data.go.kr/data/15041878/openapi.do | I3: 본 API로는 근로복지공단이 보유하고 있는 방대한 산재보험 관련 판례 판결문을 조회 할 수 있습니다.
A4: 01 법령·질의회시·Q&A·해석 | B4: ★ | C4: 오픈API | D4: 법제처_고용노동부 법령해석 목록 조회 | E4: 법제처 | F4: XML+JSON | G4: 2025-07-03 | H4: https://www.data.go.kr/data/15140236/openapi.do | I4: 본 서비스는 근로기준법, 산업안전보건법, 고용정책기본법 등 노동 관련 법령에 대해 고용노동부가 법제처에 질의한 사례들을 목록 형태로 제공합니다.
A5: 01 법령·질의회시·Q&A·해석 | B5: ★ | C5: 오픈API | D5: 법제처_고용노동부 법령해석 본문 조회 | E5: 법제처 | F5: XML+JSON | G5: 2025-07-03 | H5: https://www.data.go.kr/data/15140237/openapi.do | I5: 본 서비스는 근로기준법, 산업안전보건법, 고용정책기본법 등 고용노동부 관할 법령에 대한 질의에 대해 법제처가 회신한 해석 내용을 본문 형태로 제공합니다.
A6: 01 법령·질의회시·Q&A·해석 | B6: ★ | C6: 오픈API | D6: 법제처_법령해석례 목록 조회 | E6: 법제처 | F6: XML | G6: 2025-07-08 | H6: https://www.data.go.kr/data/15059136/openapi.do | I6: 본 데이터는 법제처에서 제공하는 법령 해석 사례의 목록 정보를 포함하고 있습니다.
A7: 01 법령·질의회시·Q&A·해석 | B7: ★ | C7: 오픈API | D7: 법제처_소방청 법령해석 목록 조회 | E7: 법제처 | F7: XML+JSON | G7: 2025-11-25 | H7: https://www.data.go.kr/data/15153132/openapi.do | I7: 법제처 국가법령정보센터에서 제공하는 소방청 법령해석 데이터로, 법령해석에 대한 목록 정보를 조회하는 서비스입니다. 본 서비스는 소방청 소관 법령 질의 및 해석 사례를 목록 형태로 제공하며, 해석일련번호, 안건명, 해석기관명, 해석일자 등의 기본 정보가 포함됩니다. 사용
A8: 01 법령·질의회시·Q&A·해석 | B8: ★ | C8: 오픈API | D8: 법제처_소방청 법령해석 본문 조회 | E8: 법제처 | F8: XML+JSON | G8: 2025-11-25 | H8: https://www.data.go.kr/data/15153134/openapi.do | I8: 본 서비스는 소방청 소관 법령 질의에 대한 법제처의 회신 내용을 본문 형태로 제공하며, 해석일련번호, 안건명, 해석일자, 기관정보, 질의요지, 회답, 이유, 관련법령 등의 항목으로
A9: 01 법령·질의회시·Q&A·해석 | B9: ★ | C9: 오픈API | D9: 법제처_행정규칙 목록 조회 | E9: 법제처 | F9: XML | G9: 2025-07-10 | H9: https://www.data.go.kr/data/15057542/openapi.do | I9: 법제처에서 제공하는 행정규칙 목록 조회 서비스 데이터입니다. 행정규칙의 일련번호, 규칙명, 소관부처, 제정·개정일자, 시행일자, 규칙코드, 행정분야 구분 등의 항목을 체계적으로 확인할 수 있습니다. 규칙명, 부처명, 규칙코드 등을 파라미터로 지정하여 원하는 목록을 선택
A10: 01 법령·질의회시·Q&A·해석 | B10: ★ | C10: 오픈API | D10: 법제처_현행법령 본문 조회 | E10: 법제처 | F10: XML | G10: 2025-07-10 | H10: https://www.data.go.kr/data/15057358/openapi.do | I10: 법제처에서 제공하는 현행법령 본문 조회 서비스 데이터입니다. 해당 데이터는 현재 효력이 발생 중인 법령의 본문을 조문 단위로 상세히 제공합니다.
A11: 01 법령·질의회시·Q&A·해석 | B11: ★ | C11: 오픈API | D11: 법제처_환경부 법령해석 목록 조회 | E11: 법제처 | F11: XML+JSON | G11: 2025-07-03 | H11: https://www.data.go.kr/data/15140241/openapi.do | I11: 제공되는 데이터는 대기질, 수질, 폐기물, 화학물질 관리 등 주요 환경 정책과 관련된 행정 해석 사례를 포괄하고 있습니다.
A12: 01 법령·질의회시·Q&A·해석 | B12: ★ | C12: 오픈API | D12: 법제처_환경부 법령해석 본문 조회 | E12: 법제처 | F12: XML+JSON | G12: 2025-07-03 | H12: https://www.data.go.kr/data/15140310/openapi.do | I12: 본 서비스는 폐기물 처리, 대기환경보전, 수질오염 방지, 화학물질 안전관리 등 환경 분야 전반에 걸쳐 환경부가 질의한 법령 해석에 대한 회신 본문을 제공합니다.
... A23: 01 법령·질의회시·Q&A·해석 | B23: ★ | C23: 파일데이터 | D23: 한국환경공단_유해화학물질 취급시설 검사 FAQ | E23: 한국환경공단 | F23: CSV | G23: 2026-08-27 | H23: https://www.data.go.kr/data/15118735/fileData.do | I23: 본 데이터는 유해화학물질 취급시설 검사 및 안전진단 시스템의 FAQ(자주 묻는 질문) 정보를 담고 있으며, 각 항목은 질문, 답변(HTML 형식), 게시여부, 등록일, 수정일로 구성되어 있음. 질문은 사용자들이 시스템 이용 중 자주 접하는 문제나 궁금증을 바탕으로 작성
A24: 01 법령·질의회시·Q&A·해석 | C24: 오픈API | D24: 국민권익위원회_고충민원 결정례 조회 서비스 | E24: 국민권익위원회 | F24: XML+JSON | G24: 2025-09-01 | H24: https://www.data.go.kr/data/15102383/openapi.do | I24: 국민이 일상생활 속에서 겪는 다양한 고충민원에 대해 2013년 이후 국민권익위원회에서 처리한 약 700여 건의 고충민원 사례를 수록한 결정례집을 기반으로 하며, 각 사례는 행정, 교육
A25: 01 법령·질의회시·Q&A·해석 | C25: 오픈API | D25: 법제처 별표,서식(행정규칙)정보 | E25: 법제처 | F25: XML | G25: 2025-07-08 | H25: https://www.data.go.kr/data/3034000/openapi.do | I25: 이러한 정보는 행정기관의 업무 수행과 관련된 법령의 해석과 적용에 있어 중요한 참고자료로 활용됩니다.
A26: 01 법령·질의회시·Q&A·해석 | C26: 오픈API | D26: 법제처_국토교통부 법령해석 목록 조회 | E26: 법제처 | F26: XML+JSON | G26: 2025-07-03 | H26: https://www.data.go.kr/data/15140238/openapi.do | I26: 본 서비스는 국토의 계획 및 이용에 관한 법률, 건축법, 주택법, 도로법 등 국토교통부 관련 법령에 대한 해석 요청 목록을 제공하며, 각 사례는 실제 행정 현장에서 제기된 법적 쟁점에
A27: 01 법령·질의회시·Q&A·해석 | C27: 오픈API | D27: 법제처_국토교통부 법령해석 본문 조회 | E27: 법제처 | F27: XML+JSON | G27: 2025-07-03 | H27: https://www.data.go.kr/data/15140240/openapi.do | I27: 법제처 국가법령정보센터에서 제공하는 국토교통부 법령해석 데이터로, 법령해석에 대한 본문 정보를 조회하는 서비스입니다.
A28: 01 법령·질의회시·Q&A·해석 | C28: 오픈API | D28: 법제처_법령 용어 목록 조회 | E28: 법제처 | F28: XML | G28: 2025-07-08 | H28: https://www.data.go.kr/data/15057595/openapi.do | I28: 법제처_법령 용어 목록 조회 데이터는 대한민국 법령에서 사용되는 주요 법률용어와 그 정의를 체계적으로 수록한 자료입니다.
A29: 01 법령·질의회시·Q&A·해석 | C29: 오픈API | D29: 법제처_법령 용어 본문 조회 | E29: 법제처 | F29: XML | G29: 2025-07-08 | H29: https://www.data.go.kr/data/15057261/openapi.do | I29: 본 데이터는 법령 내에서 사용되는 용어의 정의 및 본문 내용을 제공하는 데이터입니다.
A30: 01 법령·질의회시·Q&A·해석 | C30: 오픈API | D30: 법제처_법령해석례 | E30: 법제처 | F30: XML | G30: 2025-07-10 | H30: https://www.data.go.kr/data/15057092/openapi.do | I30: 본 데이터는 법제처에서 수집·정리한 법령에 대한 해석례를 제공하는 자료입니다.
A31: 01 법령·질의회시·Q&A·해석 | C31: 오픈API | D31: 법제처_법령해석례 본문 조회 | E31: 법제처 | F31: XML | G31: 2025-07-08 | H31: https://www.data.go.kr/data/15059402/openapi.do | I31: 본 데이터는 법제처가 제공하는 법령 해석례에 대한 전문 정보를 포함합니다. 각 사례는 질의기관명, 질의일자, 문의 법조문과 법령번호, 해당 해석일자 및 해석의견을 수록합니다.
A32: 01 법령·질의회시·Q&A·해석 | C32: 오픈API | D32: 법제처_법령해석례 상세 조회 정보 | E32: 법제처 | F32: XML | G32: 2026-01-02 | H32: https://www.data.go.kr/data/15090746/openapi.do | I32: 법제처 정부입법지원센터에서 제공하는 법령해석례에 대한 상세정보를 OPEN API형식으로 제공하여 국민 모두가 활용 용이하게끔 한 데이터입니다.
A33: 01 법령·질의회시·Q&A·해석 | C33: 오픈API | D33: 법제처_산업통상부 법령해석 목록 조회 | E33: 법제처 | F33: XML+JSON | G33: 2025-11-25 | H33: https://www.data.go.kr/data/15153062/openapi.do | I33: 법제처 국가법령정보센터에서 제공하는 산업통상부 법령해석 데이터로, 법령해석에 대한 목록 정보를 조회하는 서비스입니다.
A34: 01 법령·질의회시·Q&A·해석 | C34: 오픈API | D34: 법제처_산업통상부 법령해석 본문 조회 | E34: 법제처 | F34: XML+JSON | G34: 2025-11-25 | H34: https://www.data.go.kr/data/15153063/openapi.do | I34: 본 서비스는 산업통상부 소관 법령 질의에 대한 법제처의 회신 내용을 본문 형태로 제공하며, 해석일련번호, 안건명, 해석일자, 기관정보, 질의요지, 회답, 이유, 관련법령 등의 항목으로
A35: 01 법령·질의회시·Q&A·해석 | C35: 오픈API | D35: 법제처_자치법규 목록 조회 | E35: 법제처 | F35: XML | G35: 2025-07-09 | H35: https://www.data.go.kr/data/15057575/openapi.do | I35: 본 데이터는 각 자치법규의 명칭, 고시번호, 제정 및 개정 일자, 시행 시작일, 소관 부서, 법령상의 근거 조항, 분류 체계 및 해당 법규의 현재 시행 상태 등을 포함합니다.
... A66: 01 법령·질의회시·Q&A·해석 | C66: 파일데이터 | D66: 한국소방산업기술원_Korea Fire Code | E66: 한국소방산업기술원 | F66: CSV | G66: 2026-08-25 | H66: https://www.data.go.kr/data/15161428/fileData.do | I66: 한국소방산업기술원이 제공하는 “Korea Fire Code”는 공공질서및안전 → 안전관리 분야에 속하는 국가 차원의 화재안전 규정 데이터셋입니다.
A67: 02 화학물질·MSDS·화학사고 | B67: ★ | C67: 오픈API | D67: 기후에너지환경부 화학물질안전원_화학물질 배출 및 이동량 정보 | E67: 기후에너지환경부 화학물질안전원 | F67: XML+JSON | G67: 2022-08-02 | H67: https://www.data.go.kr/data/15024756/openapi.do | I67: 화학물질 배출로부터 국민의 건강 및 환경을 보호하고 사업장으로 하여금 자발적인 화학물질 배출의 저감을 유도하기 위하여 매년 대통령령으로 정하는 화학물질을 취급하는 사업장에 대하여 해당
A68: 02 화학물질·MSDS·화학사고 | B68: ★ | C68: 오픈API | D68: 기후에너지환경부 화학물질안전원_화학물질안전관리정보 | E68: 기후에너지환경부 화학물질안전원 | F68: XML | G68: 2025-05-23 | H68: https://www.data.go.kr/data/15072442/openapi.do | I68: 매년 유해화학물질을 취급하는 사업장과 그 사용량이 꾸준히 증가하고 있습니다. 이에 따라 국민의 안전을 확보하기 위한 체계적인 관리와 정보 제공이 더욱 중요해지고 있습니다.
A69: 02 화학물질·MSDS·화학사고 | B69: ★ | C69: 오픈API | D69: 기후에너지환경부 화학물질안전원_화학사고정보 | E69: 기후에너지환경부 화학물질안전원 | F69: XML | G69: 2025-05-26 | H69: https://www.data.go.kr/data/15072446/openapi.do | I69: 정보 제공의 목적은 전국적으로 발생하는 화학사고의 발생 현황, 원인, 물질 종류, 피해 규모 등의 정보를 체계적으로 수집·분석하여 이를 국민과 관련 기관에 투명하게 공개함으로써 국민의
A70: 02 화학물질·MSDS·화학사고 | B70: ★ | C70: 오픈API | D70: 한국산업안전보건공단_물질안전보건자료 조회 서비스 | E70: 한국산업안전보건공단 | F70: XML | G70: 2026-09-17 | H70: https://www.data.go.kr/data/15157612/openapi.do | I70: 공단 화학물질정보 시스템(https://msds.kosha.or.kr/MSDSInfo/)에서 검색가능한 화학물질 안전보건자료의 목록 및 내용을 제공합니다. - 물질안전보건자료대상물질
A71: 02 화학물질·MSDS·화학사고 | B71: ★ | C71: 오픈API | D71: 한국환경공단_유독물GHS 정보 조회 서비스 | E71: 한국환경공단 | F71: XML+JSON | G71: 2025-09-16 | H71: https://www.data.go.kr/data/15149423/openapi.do | I71: 영문 물질명, CAS번호, 고유번호 등을 기준으로 물질명(국문, 영문), 물질유형 및 고유번호, 신호어, M계수, UN번호, 그림문자코드, 유해성분류(항목명, 분류등급, 유해위험코드) 등을 제공하는 유독물GHS 정보 조회 서비스 부가설명 화학물질관리법에 따라 화학물질
A72: 02 화학물질·MSDS·화학사고 | B72: ★ | C72: 오픈API | D72: 한국환경공단_화학물질 정보 조회 서비스 | E72: 한국환경공단 | F72: XML+JSON | G72: 2025-09-16 | H72: https://www.data.go.kr/data/15149420/openapi.do | I72: CAS번호, 물질명(국문, 영문), 고유번호 등을 기준으로 물질ID, CAS번호, KE번호, 물질명(국문, 영문), 물질유사명(국문, 영문), 분자식, 분자량, 물질분류 (물질분류유형, 고유번호, 함량정보, 예외정보, 고시일자, 고시정보) 등을 제공하는 화학물질 정보
A73: 02 화학물질·MSDS·화학사고 | B73: ★ | C73: 파일데이터 | D73: 고용노동부_신규화학물질 | E73: 고용노동부 | F73: HWPX | G73: 2026-09-20 | H73: https://www.data.go.kr/data/15002450/fileData.do | I73: 고용노동부_신규화학물질 고용노동부에서 산업안전보건법 제108조제3항 및 같은 법 시행규칙 제153조에 따라 공표중인 '신규화학물질의 명칭 등의 공표' 내용의 데이터 입니다.
A74: 02 화학물질·MSDS·화학사고 | B74: ★ | C74: 파일데이터 | D74: 기후에너지환경부 국립환경과학원_특정수질유해물질배출량조사시스템_업체정보 | E74: 기후에너지환경부 국립환경과학원 | F74: CSV | G74: 2025-05-19 | H74: https://www.data.go.kr/data/15121107/fileData.do | I74: 특정수질유해물질 배출량 조사제도는 전년도말(12월31일) 까지 측정한 자료 등을 포함한 '배출량조사표'를 증빙서류와 함께 매년 3월 31일까지 시스템에 입력하는 제도로, 폐수배출시설 설치 허가를 받아 특정수질유해물질을 배출하는 사업장이 해당물질 배출량을 조사하여 제출하
A75: 02 화학물질·MSDS·화학사고 | B75: ★ | C75: 파일데이터 | D75: 기후에너지환경부 화학물질안전원_화학물질안전관리정보 | E75: 기후에너지환경부 화학물질안전원 | F75: CSV | G75: 2026-05-26 | H75: https://www.data.go.kr/data/15024880/fileData.do | I75: 매년 유해화학물질을 취급하는 사업장과 그 사용량이 꾸준히 증가하고 있습니다. 이에 따라 국민의 안전을 확보하기 위한 체계적인 관리와 정보 제공이 더욱 중요해지고 있습니다.
A76: 02 화학물질·MSDS·화학사고 | B76: ★ | C76: 파일데이터 | D76: 한국환경공단_화학물질 유해성 정보 | E76: 한국환경공단 | F76: CSV | G76: 2026-09-21 | H76: https://www.data.go.kr/data/15162938/fileData.do | I76: 화평법 산업계 도움센터에 연결된 유해성 정보 공개 시스템은 화학물질의 유해성 정보를 공개하기 위한 서비스로 물질명, CAS 번호 등을 이용하여 대상 물지르이 정보를 검색할 수 있다. 화학물질의 유해성 정보를 제공함과 동시에 해당 정보의 출처에 관한 정보를 함께 관리하고
A77: 02 화학물질·MSDS·화학사고 | B77: ★ | C77: 파일데이터 | D77: 한국환경산업기술원_유해물질 비상대응 핸드북 | E77: 한국환경산업기술원 | F77: PDF | G77: 2025-07-23 | H77: https://www.data.go.kr/data/15083811/fileData.do | I77: 본 핸드북은 유해물질 사고 발생 시 현장 대응을 위한 종합 지침을 제공하는 공공데이터입니다. 현장 접근 전 안전 주의사항, 그림문자 및 UN 번호 판독 방법, 현지 비상 연락망 작성 양식, 위험 등급 분류 체계, 초기 이격·방호 활동 거리표, 물질유형별 비상대응 지침,
A78: 02 화학물질·MSDS·화학사고 | C78: 오픈API | D78: 행정안전부_공유플랫폼_화학사고대피장소 | E78: 행정안전부 | F78: JSON | G78: 2025-05-26 | H78: https://www.data.go.kr/data/15139645/openapi.do | I78: 행정안전부에서 운영하는 재난안전데이터 공유플랫폼(https://www.safetydata.go.kr)에서 제공하는 화학사고 대피장소 정보로, 시도명, 시군구명, 대피시설순번, 시설구분
A79: 02 화학물질·MSDS·화학사고 | C79: 오픈API | D79: 행정안전부_유해화학물질취급시설안전점검결과 | E79: 행정안전부 | F79: JSON | G79: 2025-11-21 | H79: https://www.data.go.kr/data/15153441/openapi.do | I79: . - 해당 데이터는 행정안전부에서 제공하는 유해화학물질취급시설안전점검결과 정보입니다.'
A80: 02 화학물질·MSDS·화학사고 | C80: 오픈API | D80: 행정안전부_유해화학시설-폐기물처리시설 | E80: 행정안전부 | F80: WMS | G80: 2025-11-19 | H80: https://www.data.go.kr/data/15101916/openapi.do | I80: - 지역별 폐기물처리시설 업체 수를 표시한 정보입니다. - 지도상의 심벌을 클릭하시면 상세정보(업체수)를 확인할 수 있습니다.
...

Sheet 핵심(★)
A1: 분야 | B1: ★ | C1: 유형 | D1: 데이터명 | E1: 제공기관 | F1: 형식 | G1: 수정일 | H1: 링크 | I1: 설명(포털 요약)
A2: 01 법령·질의회시·Q&A·해석 | B2: ★ | C2: 오픈API | D2: 국민권익위원회_민원정책 질의응답조회서비스 | E2: 국민권익위원회 | F2: JSON | G2: 2026-09-23 | H2: https://www.data.go.kr/data/15074671/openapi.do | I2: 국민권익위원회는 민원정책에 대한 질의응답 데이터를 공개하여 공공 및 민간의 행정 연구에 활용할 수 있도록 지원하고 있습니다.
A3: 01 법령·질의회시·Q&A·해석 | B3: ★ | C3: 오픈API | D3: 근로복지공단_산재보험 판례 판결문 조회 서비스 | E3: 근로복지공단 | F3: XML | G3: 2026-01-12 | H3: https://www.data.go.kr/data/15041878/openapi.do | I3: 본 API로는 근로복지공단이 보유하고 있는 방대한 산재보험 관련 판례 판결문을 조회 할 수 있습니다.
A4: 01 법령·질의회시·Q&A·해석 | B4: ★ | C4: 오픈API | D4: 법제처_고용노동부 법령해석 목록 조회 | E4: 법제처 | F4: XML+JSON | G4: 2025-07-03 | H4: https://www.data.go.kr/data/15140236/openapi.do | I4: 본 서비스는 근로기준법, 산업안전보건법, 고용정책기본법 등 노동 관련 법령에 대해 고용노동부가 법제처에 질의한 사례들을 목록 형태로 제공합니다.
A5: 01 법령·질의회시·Q&A·해석 | B5: ★ | C5: 오픈API | D5: 법제처_고용노동부 법령해석 본문 조회 | E5: 법제처 | F5: XML+JSON | G5: 2025-07-03 | H5: https://www.data.go.kr/data/15140237/openapi.do | I5: 본 서비스는 근로기준법, 산업안전보건법, 고용정책기본법 등 고용노동부 관할 법령에 대한 질의에 대해 법제처가 회신한 해석 내용을 본문 형태로 제공합니다.
A6: 01 법령·질의회시·Q&A·해석 | B6: ★ | C6: 오픈API | D6: 법제처_법령해석례 목록 조회 | E6: 법제처 | F6: XML | G6: 2025-07-08 | H6: https://www.data.go.kr/data/15059136/openapi.do | I6: 본 데이터는 법제처에서 제공하는 법령 해석 사례의 목록 정보를 포함하고 있습니다.
A7: 01 법령·질의회시·Q&A·해석 | B7: ★ | C7: 오픈API | D7: 법제처_소방청 법령해석 목록 조회 | E7: 법제처 | F7: XML+JSON | G7: 2025-11-25 | H7: https://www.data.go.kr/data/15153132/openapi.do | I7: 법제처 국가법령정보센터에서 제공하는 소방청 법령해석 데이터로, 법령해석에 대한 목록 정보를 조회하는 서비스입니다. 본 서비스는 소방청 소관 법령 질의 및 해석 사례를 목록 형태로 제공하며, 해석일련번호, 안건명, 해석기관명, 해석일자 등의 기본 정보가 포함됩니다. 사용
A8: 01 법령·질의회시·Q&A·해석 | B8: ★ | C8: 오픈API | D8: 법제처_소방청 법령해석 본문 조회 | E8: 법제처 | F8: XML+JSON | G8: 2025-11-25 | H8: https://www.data.go.kr/data/15153134/openapi.do | I8: 본 서비스는 소방청 소관 법령 질의에 대한 법제처의 회신 내용을 본문 형태로 제공하며, 해석일련번호, 안건명, 해석일자, 기관정보, 질의요지, 회답, 이유, 관련법령 등의 항목으로
A9: 01 법령·질의회시·Q&A·해석 | B9: ★ | C9: 오픈API | D9: 법제처_행정규칙 목록 조회 | E9: 법제처 | F9: XML | G9: 2025-07-10 | H9: https://www.data.go.kr/data/15057542/openapi.do | I9: 법제처에서 제공하는 행정규칙 목록 조회 서비스 데이터입니다. 행정규칙의 일련번호, 규칙명, 소관부처, 제정·개정일자, 시행일자, 규칙코드, 행정분야 구분 등의 항목을 체계적으로 확인할 수 있습니다. 규칙명, 부처명, 규칙코드 등을 파라미터로 지정하여 원하는 목록을 선택
A10: 01 법령·질의회시·Q&A·해석 | B10: ★ | C10: 오픈API | D10: 법제처_현행법령 본문 조회 | E10: 법제처 | F10: XML | G10: 2025-07-10 | H10: https://www.data.go.kr/data/15057358/openapi.do | I10: 법제처에서 제공하는 현행법령 본문 조회 서비스 데이터입니다. 해당 데이터는 현재 효력이 발생 중인 법령의 본문을 조문 단위로 상세히 제공합니다.
A11: 01 법령·질의회시·Q&A·해석 | B11: ★ | C11: 오픈API | D11: 법제처_환경부 법령해석 목록 조회 | E11: 법제처 | F11: XML+JSON | G11: 2025-07-03 | H11: https://www.data.go.kr/data/15140241/openapi.do | I11: 제공되는 데이터는 대기질, 수질, 폐기물, 화학물질 관리 등 주요 환경 정책과 관련된 행정 해석 사례를 포괄하고 있습니다.
A12: 01 법령·질의회시·Q&A·해석 | B12: ★ | C12: 오픈API | D12: 법제처_환경부 법령해석 본문 조회 | E12: 법제처 | F12: XML+JSON | G12: 2025-07-03 | H12: https://www.data.go.kr/data/15140310/openapi.do | I12: 본 서비스는 폐기물 처리, 대기환경보전, 수질오염 방지, 화학물질 안전관리 등 환경 분야 전반에 걸쳐 환경부가 질의한 법령 해석에 대한 회신 본문을 제공합니다.
... A115: 12 시설안전(가스·전기·승강기·소방·위험물·건설·방사선) | B115: ★ | C115: 오픈API | D115: 한국승강기안전공단_승강기안전관리자정보 조회 서비스 | E115: 한국승강기안전공단 | F115: XML | G115: 2025-11-06 | H115: https://www.data.go.kr/data/15151199/openapi.do | I115: 승강기안전관리자정보 서비스로 안전관리자선임일, 승강기고유번호, 안전관리자명, 교육 이수일, 교육유효기간종료일, 교육유효기간시작일을 승강기고유번호로 조회할 수 있습니다.

Sheet 오픈API만
A1: 분야 | B1: ★ | C1: 유형 | D1: 데이터명 | E1: 제공기관 | F1: 형식 | G1: 수정일 | H1: 링크 | I1: 설명(포털 요약)
A2: 01 법령·질의회시·Q&A·해석 | B2: ★ | C2: 오픈API | D2: 국민권익위원회_민원정책 질의응답조회서비스 | E2: 국민권익위원회 | F2: JSON | G2: 2026-09-23 | H2: https://www.data.go.kr/data/15074671/openapi.do | I2: 국민권익위원회는 민원정책에 대한 질의응답 데이터를 공개하여 공공 및 민간의 행정 연구에 활용할 수 있도록 지원하고 있습니다.
A3: 01 법령·질의회시·Q&A·해석 | B3: ★ | C3: 오픈API | D3: 근로복지공단_산재보험 판례 판결문 조회 서비스 | E3: 근로복지공단 | F3: XML | G3: 2026-01-12 | H3: https://www.data.go.kr/data/15041878/openapi.do | I3: 본 API로는 근로복지공단이 보유하고 있는 방대한 산재보험 관련 판례 판결문을 조회 할 수 있습니다.
A4: 01 법령·질의회시·Q&A·해석 | B4: ★ | C4: 오픈API | D4: 법제처_고용노동부 법령해석 목록 조회 | E4: 법제처 | F4: XML+JSON | G4: 2025-07-03 | H4: https://www.data.go.kr/data/15140236/openapi.do | I4: 본 서비스는 근로기준법, 산업안전보건법, 고용정책기본법 등 노동 관련 법령에 대해 고용노동부가 법제처에 질의한 사례들을 목록 형태로 제공합니다.
A5: 01 법령·질의회시·Q&A·해석 | B5: ★ | C5: 오픈API | D5: 법제처_고용노동부 법령해석 본문 조회 | E5: 법제처 | F5: XML+JSON | G5: 2025-07-03 | H5: https://www.data.go.kr/data/15140237/openapi.do | I5: 본 서비스는 근로기준법, 산업안전보건법, 고용정책기본법 등 고용노동부 관할 법령에 대한 질의에 대해 법제처가 회신한 해석 내용을 본문 형태로 제공합니다.
A6: 01 법령·질의회시·Q&A·해석 | B6: ★ | C6: 오픈API | D6: 법제처_법령해석례 목록 조회 | E6: 법제처 | F6: XML | G6: 2025-07-08 | H6: https://www.data.go.kr/data/15059136/openapi.do | I6: 본 데이터는 법제처에서 제공하는 법령 해석 사례의 목록 정보를 포함하고 있습니다.
A7: 01 법령·질의회시·Q&A·해석 | B7: ★ | C7: 오픈API | D7: 법제처_소방청 법령해석 목록 조회 | E7: 법제처 | F7: XML+JSON | G7: 2025-11-25 | H7: https://www.data.go.kr/data/15153132/openapi.do | I7: 법제처 국가법령정보센터에서 제공하는 소방청 법령해석 데이터로, 법령해석에 대한 목록 정보를 조회하는 서비스입니다. 본 서비스는 소방청 소관 법령 질의 및 해석 사례를 목록 형태로 제공하며, 해석일련번호, 안건명, 해석기관명, 해석일자 등의 기본 정보가 포함됩니다. 사용
A8: 01 법령·질의회시·Q&A·해석 | B8: ★ | C8: 오픈API | D8: 법제처_소방청 법령해석 본문 조회 | E8: 법제처 | F8: XML+JSON | G8: 2025-11-25 | H8: https://www.data.go.kr/data/15153134/openapi.do | I8: 본 서비스는 소방청 소관 법령 질의에 대한 법제처의 회신 내용을 본문 형태로 제공하며, 해석일련번호, 안건명, 해석일자, 기관정보, 질의요지, 회답, 이유, 관련법령 등의 항목으로
A9: 01 법령·질의회시·Q&A·해석 | B9: ★ | C9: 오픈API | D9: 법제처_행정규칙 목록 조회 | E9: 법제처 | F9: XML | G9: 2025-07-10 | H9: https://www.data.go.kr/data/15057542/openapi.do | I9: 법제처에서 제공하는 행정규칙 목록 조회 서비스 데이터입니다. 행정규칙의 일련번호, 규칙명, 소관부처, 제정·개정일자, 시행일자, 규칙코드, 행정분야 구분 등의 항목을 체계적으로 확인할 수 있습니다. 규칙명, 부처명, 규칙코드 등을 파라미터로 지정하여 원하는 목록을 선택
A10: 01 법령·질의회시·Q&A·해석 | B10: ★ | C10: 오픈API | D10: 법제처_현행법령 본문 조회 | E10: 법제처 | F10: XML | G10: 2025-07-10 | H10: https://www.data.go.kr/data/15057358/openapi.do | I10: 법제처에서 제공하는 현행법령 본문 조회 서비스 데이터입니다. 해당 데이터는 현재 효력이 발생 중인 법령의 본문을 조문 단위로 상세히 제공합니다.
A11: 01 법령·질의회시·Q&A·해석 | B11: ★ | C11: 오픈API | D11: 법제처_환경부 법령해석 목록 조회 | E11: 법제처 | F11: XML+JSON | G11: 2025-07-03 | H11: https://www.data.go.kr/data/15140241/openapi.do | I11: 제공되는 데이터는 대기질, 수질, 폐기물, 화학물질 관리 등 주요 환경 정책과 관련된 행정 해석 사례를 포괄하고 있습니다.
A12: 01 법령·질의회시·Q&A·해석 | B12: ★ | C12: 오픈API | D12: 법제처_환경부 법령해석 본문 조회 | E12: 법제처 | F12: XML+JSON | G12: 2025-07-03 | H12: https://www.data.go.kr/data/15140310/openapi.do | I12: 본 서비스는 폐기물 처리, 대기환경보전, 수질오염 방지, 화학물질 안전관리 등 환경 분야 전반에 걸쳐 환경부가 질의한 법령 해석에 대한 회신 본문을 제공합니다.
... A14: 01 법령·질의회시·Q&A·해석 | B14: ★ | C14: 오픈API | D14: 한국산업안전보건공단_안전보건법령 스마트검색 | E14: 한국산업안전보건공단 | F14: JSON | G14: 2026-08-12 | H14: https://www.data.go.kr/data/15123696/openapi.do | I14: 산업안전보건법.령.규칙, 기준에 관한 규칙.고시.훈령.예규, 중대재해처벌법.령, 안전보건기술지침(KOSHA GUIDE), 안전보건 미디어 자료, 유해·위험작업의 취업 제한에 관한 규칙
A15: 01 법령·질의회시·Q&A·해석 | C15: 오픈API | D15: 국민권익위원회_고충민원 결정례 조회 서비스 | E15: 국민권익위원회 | F15: XML+JSON | G15: 2025-09-01 | H15: https://www.data.go.kr/data/15102383/openapi.do | I15: 국민이 일상생활 속에서 겪는 다양한 고충민원에 대해 2013년 이후 국민권익위원회에서 처리한 약 700여 건의 고충민원 사례를 수록한 결정례집을 기반으로 하며, 각 사례는 행정, 교육
A16: 01 법령·질의회시·Q&A·해석 | C16: 오픈API | D16: 법제처 별표,서식(행정규칙)정보 | E16: 법제처 | F16: XML | G16: 2025-07-08 | H16: https://www.data.go.kr/data/3034000/openapi.do | I16: 이러한 정보는 행정기관의 업무 수행과 관련된 법령의 해석과 적용에 있어 중요한 참고자료로 활용됩니다.
A17: 01 법령·질의회시·Q&A·해석 | C17: 오픈API | D17: 법제처_국토교통부 법령해석 목록 조회 | E17: 법제처 | F17: XML+JSON | G17: 2025-07-03 | H17: https://www.data.go.kr/data/15140238/openapi.do | I17: 본 서비스는 국토의 계획 및 이용에 관한 법률, 건축법, 주택법, 도로법 등 국토교통부 관련 법령에 대한 해석 요청 목록을 제공하며, 각 사례는 실제 행정 현장에서 제기된 법적 쟁점에
A18: 01 법령·질의회시·Q&A·해석 | C18: 오픈API | D18: 법제처_국토교통부 법령해석 본문 조회 | E18: 법제처 | F18: XML+JSON | G18: 2025-07-03 | H18: https://www.data.go.kr/data/15140240/openapi.do | I18: 법제처 국가법령정보센터에서 제공하는 국토교통부 법령해석 데이터로, 법령해석에 대한 본문 정보를 조회하는 서비스입니다.
A19: 01 법령·질의회시·Q&A·해석 | C19: 오픈API | D19: 법제처_법령 용어 목록 조회 | E19: 법제처 | F19: XML | G19: 2025-07-08 | H19: https://www.data.go.kr/data/15057595/openapi.do | I19: 법제처_법령 용어 목록 조회 데이터는 대한민국 법령에서 사용되는 주요 법률용어와 그 정의를 체계적으로 수록한 자료입니다.
A20: 01 법령·질의회시·Q&A·해석 | C20: 오픈API | D20: 법제처_법령 용어 본문 조회 | E20: 법제처 | F20: XML | G20: 2025-07-08 | H20: https://www.data.go.kr/data/15057261/openapi.do | I20: 본 데이터는 법령 내에서 사용되는 용어의 정의 및 본문 내용을 제공하는 데이터입니다.
A21: 01 법령·질의회시·Q&A·해석 | C21: 오픈API | D21: 법제처_법령해석례 | E21: 법제처 | F21: XML | G21: 2025-07-10 | H21: https://www.data.go.kr/data/15057092/openapi.do | I21: 본 데이터는 법제처에서 수집·정리한 법령에 대한 해석례를 제공하는 자료입니다.
A22: 01 법령·질의회시·Q&A·해석 | C22: 오픈API | D22: 법제처_법령해석례 본문 조회 | E22: 법제처 | F22: XML | G22: 2025-07-08 | H22: https://www.data.go.kr/data/15059402/openapi.do | I22: 본 데이터는 법제처가 제공하는 법령 해석례에 대한 전문 정보를 포함합니다. 각 사례는 질의기관명, 질의일자, 문의 법조문과 법령번호, 해당 해석일자 및 해석의견을 수록합니다.
A23: 01 법령·질의회시·Q&A·해석 | C23: 오픈API | D23: 법제처_법령해석례 상세 조회 정보 | E23: 법제처 | F23: XML | G23: 2026-01-02 | H23: https://www.data.go.kr/data/15090746/openapi.do | I23: 법제처 정부입법지원센터에서 제공하는 법령해석례에 대한 상세정보를 OPEN API형식으로 제공하여 국민 모두가 활용 용이하게끔 한 데이터입니다.
A24: 01 법령·질의회시·Q&A·해석 | C24: 오픈API | D24: 법제처_산업통상부 법령해석 목록 조회 | E24: 법제처 | F24: XML+JSON | G24: 2025-11-25 | H24: https://www.data.go.kr/data/15153062/openapi.do | I24: 법제처 국가법령정보센터에서 제공하는 산업통상부 법령해석 데이터로, 법령해석에 대한 목록 정보를 조회하는 서비스입니다.
A25: 01 법령·질의회시·Q&A·해석 | C25: 오픈API | D25: 법제처_산업통상부 법령해석 본문 조회 | E25: 법제처 | F25: XML+JSON | G25: 2025-11-25 | H25: https://www.data.go.kr/data/15153063/openapi.do | I25: 본 서비스는 산업통상부 소관 법령 질의에 대한 법제처의 회신 내용을 본문 형태로 제공하며, 해석일련번호, 안건명, 해석일자, 기관정보, 질의요지, 회답, 이유, 관련법령 등의 항목으로
A26: 01 법령·질의회시·Q&A·해석 | C26: 오픈API | D26: 법제처_자치법규 목록 조회 | E26: 법제처 | F26: XML | G26: 2025-07-09 | H26: https://www.data.go.kr/data/15057575/openapi.do | I26: 본 데이터는 각 자치법규의 명칭, 고시번호, 제정 및 개정 일자, 시행 시작일, 소관 부서, 법령상의 근거 조항, 분류 체계 및 해당 법규의 현재 시행 상태 등을 포함합니다.
... A33: 01 법령·질의회시·Q&A·해석 | C33: 오픈API | D33: 법제처_현행법령 본문 조항호목 조회 | E33: 법제처 | F33: XML | G33: 2025-07-08 | H33: https://www.data.go.kr/data/15058878/openapi.do | I33: 본 데이터는 현행 법령의 본문 내 조항 및 호목 단위로 상세 조회가 가능한 정보를 제공합니다.
A34: 02 화학물질·MSDS·화학사고 | B34: ★ | C34: 오픈API | D34: 기후에너지환경부 화학물질안전원_화학물질 배출 및 이동량 정보 | E34: 기후에너지환경부 화학물질안전원 | F34: XML+JSON | G34: 2022-08-02 | H34: https://www.data.go.kr/data/15024756/openapi.do | I34: 화학물질 배출로부터 국민의 건강 및 환경을 보호하고 사업장으로 하여금 자발적인 화학물질 배출의 저감을 유도하기 위하여 매년 대통령령으로 정하는 화학물질을 취급하는 사업장에 대하여 해당
A35: 02 화학물질·MSDS·화학사고 | B35: ★ | C35: 오픈API | D35: 기후에너지환경부 화학물질안전원_화학물질안전관리정보 | E35: 기후에너지환경부 화학물질안전원 | F35: XML | G35: 2025-05-23 | H35: https://www.data.go.kr/data/15072442/openapi.do | I35: 매년 유해화학물질을 취급하는 사업장과 그 사용량이 꾸준히 증가하고 있습니다. 이에 따라 국민의 안전을 확보하기 위한 체계적인 관리와 정보 제공이 더욱 중요해지고 있습니다.
A36: 02 화학물질·MSDS·화학사고 | B36: ★ | C36: 오픈API | D36: 기후에너지환경부 화학물질안전원_화학사고정보 | E36: 기후에너지환경부 화학물질안전원 | F36: XML | G36: 2025-05-26 | H36: https://www.data.go.kr/data/15072446/openapi.do | I36: 정보 제공의 목적은 전국적으로 발생하는 화학사고의 발생 현황, 원인, 물질 종류, 피해 규모 등의 정보를 체계적으로 수집·분석하여 이를 국민과 관련 기관에 투명하게 공개함으로써 국민의
A37: 02 화학물질·MSDS·화학사고 | B37: ★ | C37: 오픈API | D37: 한국산업안전보건공단_물질안전보건자료 조회 서비스 | E37: 한국산업안전보건공단 | F37: XML | G37: 2026-09-17 | H37: https://www.data.go.kr/data/15157612/openapi.do | I37: 공단 화학물질정보 시스템(https://msds.kosha.or.kr/MSDSInfo/)에서 검색가능한 화학물질 안전보건자료의 목록 및 내용을 제공합니다. - 물질안전보건자료대상물질
A38: 02 화학물질·MSDS·화학사고 | B38: ★ | C38: 오픈API | D38: 한국환경공단_유독물GHS 정보 조회 서비스 | E38: 한국환경공단 | F38: XML+JSON | G38: 2025-09-16 | H38: https://www.data.go.kr/data/15149423/openapi.do | I38: 영문 물질명, CAS번호, 고유번호 등을 기준으로 물질명(국문, 영문), 물질유형 및 고유번호, 신호어, M계수, UN번호, 그림문자코드, 유해성분류(항목명, 분류등급, 유해위험코드) 등을 제공하는 유독물GHS 정보 조회 서비스 부가설명 화학물질관리법에 따라 화학물질
A39: 02 화학물질·MSDS·화학사고 | B39: ★ | C39: 오픈API | D39: 한국환경공단_화학물질 정보 조회 서비스 | E39: 한국환경공단 | F39: XML+JSON | G39: 2025-09-16 | H39: https://www.data.go.kr/data/15149420/openapi.do | I39: CAS번호, 물질명(국문, 영문), 고유번호 등을 기준으로 물질ID, CAS번호, KE번호, 물질명(국문, 영문), 물질유사명(국문, 영문), 분자식, 분자량, 물질분류 (물질분류유형, 고유번호, 함량정보, 예외정보, 고시일자, 고시정보) 등을 제공하는 화학물질 정보
A40: 02 화학물질·MSDS·화학사고 | C40: 오픈API | D40: 행정안전부_공유플랫폼_화학사고대피장소 | E40: 행정안전부 | F40: JSON | G40: 2025-05-26 | H40: https://www.data.go.kr/data/15139645/openapi.do | I40: 행정안전부에서 운영하는 재난안전데이터 공유플랫폼(https://www.safetydata.go.kr)에서 제공하는 화학사고 대피장소 정보로, 시도명, 시군구명, 대피시설순번, 시설구분
A41: 02 화학물질·MSDS·화학사고 | C41: 오픈API | D41: 행정안전부_유해화학물질취급시설안전점검결과 | E41: 행정안전부 | F41: JSON | G41: 2025-11-21 | H41: https://www.data.go.kr/data/15153441/openapi.do | I41: . - 해당 데이터는 행정안전부에서 제공하는 유해화학물질취급시설안전점검결과 정보입니다.'
A42: 02 화학물질·MSDS·화학사고 | C42: 오픈API | D42: 행정안전부_유해화학시설-폐기물처리시설 | E42: 행정안전부 | F42: WMS | G42: 2025-11-19 | H42: https://www.data.go.kr/data/15101916/openapi.do | I42: - 지역별 폐기물처리시설 업체 수를 표시한 정보입니다. - 지도상의 심벌을 클릭하시면 상세정보(업체수)를 확인할 수 있습니다.
A43: 02 화학물질·MSDS·화학사고 | C43: 오픈API | D43: 행정안전부_유해화학시설-환경배출시설 | E43: 행정안전부 | F43: WMS | G43: 2025-11-19 | H43: https://www.data.go.kr/data/15101922/openapi.do | I43: - 지역별 환경배출시설 업체 수를 표시한 정보입니다. - 지도상의 심벌을 클릭하시면 상세정보(업체수)를 확인할 수 있습니다.
A44: 02 화학물질·MSDS·화학사고 | C44: 오픈API | D44: 행정안전부_유해화학시설통계-폐기물처리시설 | E44: 행정안전부 | F44: WMS | G44: 2025-11-19 | H44: https://www.data.go.kr/data/15101918/openapi.do | I44: - 폐기물처리시설 위치를 표시한 정보입니다. - 지도상의 심벌을 클릭하시면 상세정보(업체명,업종,도로명주소)를 확인할 수 있습니다.
A45: 02 화학물질·MSDS·화학사고 | C45: 오픈API | D45: 행정안전부_유해화학시설통계-환경배출시설 | E45: 행정안전부 | F45: WMS | G45: 2025-11-19 | H45: https://www.data.go.kr/data/15101924/openapi.do | I45: . * 종류( 사업장의 규모별 구분(제44조제2항 관련) ) 제1종 사업장 : 1일 폐수배출량이 2,000㎥ 이상인 사업장 제2종 사업장 : 1일 폐수배출량이 700㎥ 이상, 2,000
A46: 03 작업환경·보건관리·건강진단 | B46: ★ | C46: 오픈API | D46: 한국산업안전보건공단_업무상 질병사례 게시판 조회서비스 | E46: 한국산업안전보건공단 | F46: JSON | G46: 2026-09-08 | H46: https://www.data.go.kr/data/15163160/openapi.do | I46: 한국산업안전보건공단에서 제공하는 업무상 질병 및 직업성 질병 관련 사고사례 정보를 제공하는 API입니다.
A47: 03 작업환경·보건관리·건강진단 | C47: 오픈API | D47: 한국산업안전보건공단_업무상 질병사례 게시판 첨부파일 조회서비스 | E47: 한국산업안전보건공단 | F47: JSON | G47: 2026-09-08 | H47: https://www.data.go.kr/data/15163166/openapi.do | I47: 한국산업안전보건공단 산업안전포털에서 제공하는 업무상 질병사례 게시물에 등록된 첨부파일 정보를 조회하기 위한 서비스입니다.
...

Sheet 포털 외 자료
A1: 자료명 | B1: 기관 | C1: 형식 | D1: 비고 | E1: 링크
A2: 물질안전보건자료(MSDS) 질의회시집(2023 개정판) | B2: 고용노동부(화학사고예방과) | C2: PDF | D2: data.go.kr 미등록. 고용노동부 누리집 주요발간자료 | E2: https://moel.go.kr/info/publicdata/majorpublish/majorPublishView.do?bbs_seq=20230901622
A3: 지정폐기물 질의·회신 사례집 (2026.4 배포) | B3: 기후에너지환경부 원주지방환경청(자원순환과) | C3: 책자/PDF | D3: data.go.kr 미등록. 원주청 누리집 게시 예정으로 보도됨(지정폐기물 해당여부, 보관시설, 상황별 처리방법) | E3: https://www.yna.co.kr/view/AKR20260430191000062
A4: 지정폐기물 배출 사업장 적정 관리 가이드라인 리플릿 (2026.7) | B4: 기후에너지환경부 원주지방환경청 | C4: 리플릿 | D4: 보관기준·기간, 처리방법, 올바로 인계서, 유해성정보자료 작성 의무 등 | E4: https://www.mcee.go.kr/wonju/web/board/read.do?boardId=1875150&boardMasterId=258&condition.hideCate=1&menuId=1056
A5: 행정해석(질의회시) 게시판 | B5: 고용노동부 | C5: 웹 | D5: 산업안전보건 등 행정해석 원문 검색 (data.go.kr에는 "노동포털 질의회시_AI친화 학습데이터"로 일부 개방) | E5: https://moel.go.kr/info/publicdata/qnrinfo/qnrInfoList.do
A6: 재해조사보고서 공개 | B6: 고용노동부 | C6: 웹 | D6: 중대재해 재해조사보고서 공개 게시판 | E6: https://moel.go.kr/info/dsstExaminRpt/list.do
